## 16.3 unittest: 자동화된 테스팅 프레임워크

`unittest`의 자동화된 테스팅 프레임워크는 켄트 벡(Kent Beck)과 에리히 감마(Erich Gamma)가 디자인한 XUnit 프레임워크에 기반을 둔다. C, 펄, 자바, 스몰토크(Smalltalk)같은 다른 많은 언어도 같은 패턴을 갖고 있다. `unittest`에 의해 구현된 프레임워크는 테스트 자동화가 가능하도록 픽스처, 테스트 스위트 테스트 러너를 지원한다.

### 16.3.1 기본 테스트 구조
`unittest`에 의해 정의된 테스트는 픽스처라고 불리는 테스트 종속성을 관리하는 코드와 테스트 자체 두 부분으로 구성된다. 개별 테스트는 TestCase를 서브클래싱해 필요한 기능을 오버라이드하거나 적절한 메서드를 추가해 생성한다. 다음 예제에서 SimplisticTest는 하나의 test() 메서드를 가지며, a와 b가 다른 경우 테스트가 실패한다.

```python
# unittest_simple.py
import unittest

class SimplisticTest(unittest.TestCase):
    def test(self):
        a = 'a'
        b = 'a'
        self.assertEqual(a, b)
```

### 16.3.2 테스트 실행
`unittest`로 테스트를 실행하는 가장 쉬운 방법은 커맨드라인 인터페이스를 사용하는 것이다.

```
$ python38 -m unittest unittest_simple.py
.
----------------------------------------------------------------------
Ran 1 test in 0.000s

OK
```

출력 결과에는 각 테스트에 대한 상태 표시와 테스트가 수행된 식산이 표시된다. 첫번째 줄에 있는 '.'은 테스트가 통과했음을 의미한다. 테스트 결과에 대한 좀더 자세한 사항은 -v 옵션을 통해 볼 수 있다.

```
$ python38 -m unittest -v unittest_simple.py
test (unittest_simple.SimplisticTest) ... ok

----------------------------------------------------------------------
Ran 1 test in 0.000s

OK
```

### 16.3.3 테스트 결과
테스트를 통과 시키는 명시적인 방법이 없으므로 테스트의 상태는 예외의 존재 여부에 따라 결정된다.

- 테스트 케이스 결과
    - `ok`: 테스트 통과
    - `FAIL`: 테스트 실패, AssertionError 예외를 발생시킨다.
    - `ERROR`: 테스트는 AssertionError가 아닌 예외를 발생시킨다.

```python
# unittest_outcomes.py
import unittest

class OutcomesTest(unittest.TestCase):
    def testPass(self):
        return

    def testFail(self):
        self.assertFalse(True)

    def testError(self):
        raise RuntimeError('Test error!')
```

테스트가 실패하거나 에러가 발생되면 트레이스백이 출력에 포함된다.

```
$ python38 -m unittest unittest_outcomes.py
EF.
======================================================================
ERROR: testError (unittest_outcomes.OutcomesTest)
----------------------------------------------------------------------
Traceback (most recent call last):
  File "unittest_outcomes.py", line 13, in testError
    raise RuntimeError('Test error!')
RuntimeError: Test error!

======================================================================
FAIL: testFail (unittest_outcomes.OutcomesTest)
----------------------------------------------------------------------
Traceback (most recent call last):
  File "unittest_outcomes.py", line 10, in testFail
    self.assertFalse(True)
AssertionError: True is not false

----------------------------------------------------------------------
Ran 3 tests in 0.001s

FAILED (failures=1, errors=1)
```

앞의 예제에서 testFail()은 실패하고 트레이스백이 코드에서 실패가 발생한 줄을 보여준다. 하지만 코드를 보고 실패한 테스트의 의미를 알아내는 것은 테스트 결과를 읽는 사람에 달려 있다.

```python
# unittest_failwithmessage.py
import unittest

class FailureMessageTest(unittest.TestCase):
    def testFail(self):
        self.assertFalse(True, 'failure message goes hre')
```

fail*()와 assert*() 메서드에 인자로 msg를 사용하면 더 상세한 에러 메시지를 생성하므로 테스트 실패를 더 쉽게 이해할 수 있다.

```
$ python38 -m unittest -v unittest_failwithmessage.py
testFail (unittest_failwithmessage.FailureMessageTest) ... FAIL

======================================================================
FAIL: testFail (unittest_failwithmessage.FailureMessageTest)
----------------------------------------------------------------------
Traceback (most recent call last):
  File "unittest_failwithmessage.py", line 7, in testFail
    self.assertFalse(True, 'failure message goes hre')
AssertionError: True is not false : failure message goes hre

----------------------------------------------------------------------
Ran 1 test in 0.000s

FAILED (failures=1)
```

### 16.3.4 참 여부 확인
대부분의 테스트는 특정 조건이 참인지 여부를 확인한다. 참 여부를 체크하는 테스트는 테스트 작성자와 테스트하는 코드가 원하는 결과에 따라 두 가지 방식으로 작성할수 있다.

```python
# unittest_truth.py
import unittest

class TruthTest(unittest.TestCase):
    def testAssertTrue(self):
        self.assertTrue(True)

    def testAssertFalse(self):
        self.assertFalse(False)
```

코드가 참으로 평가될 수 있는 값을 생성한다면 assertTrue() 메서드를 사용해야 한다. 코드가 거짓인 값을 생성한다면 assertFalse() 메서드를 사용한다.

```
$ python38 -m unittest -v unittest_truth.py
testAssertFalse (unittest_truth.TruthTest) ... ok
testAssertTrue (unittest_truth.TruthTest) ... ok

----------------------------------------------------------------------
Ran 2 tests in 0.000s

OK
```

### 16.3.5 동일성 테스트
unittest는 두 값의 동일성 여부를 테스트하는 메서드도 제공한다.

```python
# unittest_equality.py
import unittest

class EqualityTest(unittest.TestCase):
    def testExpectEqual(self):
        self.assertEqual(1, 3 - 2)

    def testExpectEqualFails(self):
        self.assertEqual(2, 3 - 2)

    def testExpectNotEqual(self):
        self.assertNotEqual(2, 3 - 2)

    def testExpectNotEqualFails(self):
        self.assertNotEqual(1, 3 - 2)     
```

테스트가 실패하면 이 특별한 테스트 메서드는 비교되는 값들을 식별해주는 에러 메시지를 출력한다.

```
$ python38 -m unittest unittest_equality.py
testExpectEqual (unittest_equality.EqualityTest) ... ok
testExpectEqualFails (unittest_equality.EqualityTest) ... FAIL
testExpectNotEqual (unittest_equality.EqualityTest) ... ok
testExpectNotEqualFails (unittest_equality.EqualityTest) ... FAIL

======================================================================
FAIL: testExpectEqualFails (unittest_equality.EqualityTest)
----------------------------------------------------------------------
Traceback (most recent call last):
  File "unittest_equality.py", line 10, in testExpectEqualFails
    self.assertEqual(2, 3 - 2)
AssertionError: 2 != 1

======================================================================
FAIL: testExpectNotEqualFails (unittest_equality.EqualityTest)
----------------------------------------------------------------------
Traceback (most recent call last):
  File "unittest_equality.py", line 16, in testExpectNotEqualFails
    self.assertNotEqual(1, 3 - 2)
AssertionError: 1 == 1

----------------------------------------------------------------------
Ran 4 tests in 0.001s

FAILED (failures=2)
```

### 16.3.6 거의 같은가?
엄격한 동일성 테스트 외에 추가적으로 assertAlmostEqual()과 assertNotAlmostEqual()을 사용해 두 개의 부동소수점 수가 거의 같은지 여부를 테스트 할 수 있다.

```python
# unittest_almostequal.py
import unittest

class AlmostEqualTest(unittest.TestCase):
    def testEqual(self):
        self.assertEqual(1.1, 3.3 - 2.2)

    def testAlmostEqual(self):
        self.assertAlmostEqual(1.1, 3.3 - 2.2, places=1)

    def testNotAlmostEqual(self):
        self.assertNotAlmostEqual(1.1, 3.3 - 2.0, places=1)
```

인자는 비교에 사용할 값들과 테스트에 사용할 소수점 자리를 나타내는 소수 자리의 수다.

```
$ python38 -m unittest unittest_almostequal.py
.F.
======================================================================
FAIL: testEqual (unittest_almostequal.AlmostEqualTest)
----------------------------------------------------------------------
Traceback (most recent call last):
  File "/Users/youngjae/PycharmProjects/hwangyoungjae.github.io/example/16.3_unittest/unittest_almostequal.py", line 7, in testEqual
    self.assertEqual(1.1, 3.3 - 2.2)
AssertionError: 1.1 != 1.0999999999999996

----------------------------------------------------------------------
Ran 3 tests in 0.000s

FAILED (failures=1)
```

### 16.3.7 컨테이너
assertEqual()과 assertNotEqual() 메서드 외에도 리스트, 딕셔너리, 집합 객체와 같은 컨테이너를 비교하는 메서드도 제공된다.

```python
# unittest_equality_container.py
import textwrap
import unittest

class ContainerEqualityTest(unittest.TestCase):
    def testCount(self):
        self.assertCountEqual(['a', 'b', 'c', 'b'], ['a', 'c', 'b', 'c'])

    def testDict(self):
        self.assertDictEqual({'a': 1, 'b': 2}, {'a': 1, 'b': 3})

    def testList(self):
        self.assertListEqual(['a', 'b', 'c'], ['a', 'c', 'b'])

    def testMultiLineString(self):
        self.assertMultiLineEqual(
            textwrap.dedent("""
            This string
            has more than one
            line.
            """),
            textwrap.dedent("""
            This string has
            more than two
            lines.
            """)
        )

    def testSequence(self):
        self.assertSequenceEqual(['a', 'b', 'c'], ['a', 'c', 'b'])

    def testSet(self):
        self.assertSetEqual(set(['a', 'b', 'c']), set(['a', 'c', 'b', 'd']))

    def testTuple(self):
        self.assertTupleEqual((1, 'a'), (1, 'b'))
```

위와 같은 메서드는 입력 타입에 따라 알기 쉬운 형태로 비동일성을 보고하므로 테스트 실패를 더 쉽게 이해하고 수정할 수 있다.

```
$ python38 -m unittest unittest_equality_container.py
FFFFFFF
======================================================================
FAIL: testCount (unittest_equality_container.ContainerEqualityTest)
----------------------------------------------------------------------
Traceback (most recent call last):
  File "unittest_equality_container.py", line 8, in testCount
    self.assertCountEqual(['a', 'b', 'c', 'b'], ['a', 'c', 'b', 'c'])
AssertionError: Element counts were not equal:
First has 2, Second has 1:  'b'
First has 1, Second has 2:  'c'

======================================================================
FAIL: testDict (unittest_equality_container.ContainerEqualityTest)
----------------------------------------------------------------------
Traceback (most recent call last):
  File "unittest_equality_container.py", line 11, in testDict
    self.assertDictEqual({'a': 1, 'b': 2}, {'a': 1, 'b': 3})
AssertionError: {'a': 1, 'b': 2} != {'a': 1, 'b': 3}
- {'a': 1, 'b': 2}
?               ^

+ {'a': 1, 'b': 3}
?               ^


======================================================================
FAIL: testList (unittest_equality_container.ContainerEqualityTest)
----------------------------------------------------------------------
Traceback (most recent call last):
  File "unittest_equality_container.py", line 14, in testList
    self.assertListEqual(['a', 'b', 'c'], ['a', 'c', 'b'])
AssertionError: Lists differ: ['a', 'b', 'c'] != ['a', 'c', 'b']

First differing element 1:
'b'
'c'

- ['a', 'b', 'c']
+ ['a', 'c', 'b']

======================================================================
FAIL: testMultiLineString (unittest_equality_container.ContainerEqualityTest)
----------------------------------------------------------------------
Traceback (most recent call last):
  File "unittest_equality_container.py", line 17, in testMultiLineString
    self.assertMultiLineEqual(
AssertionError: '\nThis string\nhas more than one\nline.\n' != '\nThis string has\nmore than two\nlines.\n'
  
- This string
+ This string has
?            ++++
- has more than one
? ----           --
+ more than two
?           ++
- line.
+ lines.
?     +


======================================================================
FAIL: testSequence (unittest_equality_container.ContainerEqualityTest)
----------------------------------------------------------------------
Traceback (most recent call last):
  File "unittest_equality_container.py", line 31, in testSequence
    self.assertSequenceEqual(['a', 'b', 'c'], ['a', 'c', 'b'])
AssertionError: Sequences differ: ['a', 'b', 'c'] != ['a', 'c', 'b']

First differing element 1:
'b'
'c'

- ['a', 'b', 'c']
+ ['a', 'c', 'b']

======================================================================
FAIL: testSet (unittest_equality_container.ContainerEqualityTest)
----------------------------------------------------------------------
Traceback (most recent call last):
  File "unittest_equality_container.py", line 34, in testSet
    self.assertSetEqual(set(['a', 'b', 'c']), set(['a', 'c', 'b', 'd']))
AssertionError: Items in the second set but not the first:
'd'

======================================================================
FAIL: testTuple (unittest_equality_container.ContainerEqualityTest)
----------------------------------------------------------------------
Traceback (most recent call last):
  File "unittest_equality_container.py", line 37, in testTuple
    self.assertTupleEqual((1, 'a'), (1, 'b'))
AssertionError: Tuples differ: (1, 'a') != (1, 'b')

First differing element 1:
'a'
'b'

- (1, 'a')
?      ^

+ (1, 'b')
?      ^


----------------------------------------------------------------------
Ran 7 tests in 0.002s

FAILED (failures=7)
```

컨테이너 멤버십을 테스트하려면 assertIn()을 사용한다.

```python
# unittest_in.py
import unittest

class ContainerMembershipTest(unittest.TestCase):
    def testDict(self):
        self.assertIn(4, {1: 'a', 2: 'b', 3: 'c'})

    def testList(self):
        self.assertIn(4, [1, 2, 3])

    def testSet(self):
        self.assertIn(4, set([1, 2, 3]))
```

in 연산자나 컨테이너 API를 지원하는 모든 객체는 assertIn()을 사용할 수 있다.

```
$ python38 -m unittest unittest_in.py
FFF
======================================================================
FAIL: testDict (unittest_in.ContainerMembershipTest)
----------------------------------------------------------------------
Traceback (most recent call last):
  File "unittest_in.py", line 7, in testDict
    self.assertIn(4, {1: 'a', 2: 'b', 3: 'c'})
AssertionError: 4 not found in {1: 'a', 2: 'b', 3: 'c'}

======================================================================
FAIL: testList (unittest_in.ContainerMembershipTest)
----------------------------------------------------------------------
Traceback (most recent call last):
  File "unittest_in.py", line 10, in testList
    self.assertIn(4, [1, 2, 3])
AssertionError: 4 not found in [1, 2, 3]

======================================================================
FAIL: testSet (unittest_in.ContainerMembershipTest)
----------------------------------------------------------------------
Traceback (most recent call last):
  File "unittest_in.py", line 13, in testSet
    self.assertIn(4, set([1, 2, 3]))
AssertionError: 4 not found in {1, 2, 3}

----------------------------------------------------------------------
Ran 3 tests in 0.001s

FAILED (failures=3)
```

### 16.3.8 예외에 대한 테스트
앞에서 언급했듯이 테스트가 AssertionError가 아닌 예외를 발생하면 에러로 처리된다. 이는 테스트 코드를 수정할 때 발생하는 실수를 발견하고자 사용될 수 있다. 하지만 경우에 따라 코드에서 의도된 예외가 발생하는지 확인해야 할 때도 있다. 예를 들어 객체의 속성에 잘못된 값이 주어졌을 때 테스트에서 예외를 잡아내는 것보다 assertRaises()를 사용하는 것이 더 코드가 깔끔하다. 다음 예제로 이 두개의 테스트를 비교해보자

```python
# unittest_exception.py
import unittest


def raises_error(*args, **kwargs):
    raise ValueError(f"Invalid value: {args} {kwargs}")


class ExceptionTest(unittest.TestCase):
    def testTrapLocally(self):
        try:
            raises_error('a', b='c')
        except ValueError:
            pass
        else:
            self.fail("Did not see ValueError")

    def testAssertRaises(self):
        self.assertRaises(ValueError, raises_error, 'a', b='c')
```

두 테스트의 결과는 동일하지만 assertRaises()를 사용한 두번째 테스트가 더 간결한다.

```
$ python38 -m unittest -v unittest_exception.py
testAssertRaises (unittest_exception.ExceptionTest) ... ok
testTrapLocally (unittest_exception.ExceptionTest) ... ok

----------------------------------------------------------------------
Ran 2 tests in 0.000s

OK
```

### 16.3.9 테스트 픽스처
픽스처는 테스트에 필요한 외부 리소스를 말한다. 예를 들어 한 클래스를 테스트하고자 구성 설정이나 다른 공유 리소스를 제공하는 다른 클래스의 인스턴스가 필요할 수 있다. 테스트 픽스처에는 데이터베이스 연결과 임시 파일도 포함된다. 많은 사람이 이런 외부 리소스를 사용하는 테스트는 '유닛' 테스트가 아니라고 주장하겠지만 이것도 여전히 테스트며 매우 유용하다.

unittest는 테스트에 필요한 픽스처를 구성하고 제거하는 특별한 훅을 갖고 있다. 각 개별테스트에 대해 픽스처를 설정할 때는 TestCase에 setUp()을 오버라이드한다. 설정한 픽스처를 해제하려면 tearDown()을 오버라이드한다. 테스트 클래스의 모든 인스턴스의 픽스처 설정을 관리하려면 TestCase의 클래스 메서드인 setUpClass()와 tearDownClass()를 오버라이드 한다. 마지막으로 모듈 내의 모든 테스트의 설정 작업을 하려면 모듈 레벨 함수인 setUpModule()과 tearDownModule()을 사용한다.

```python
# unittest_fixtures.py
import random
import unittest

def setupModule():
    print("In setupModule()")

def tearDownModule():
    print("In tearDownModule()")

class FixturesTest(unittest.TestCase):

    @classmethod
    def setUpClass(cls) -> None:
        print("In setUpClass()")
        cls.good_range = range(1, 10)

    @classmethod
    def tearDownClass(cls) -> None:
        print("In tearDownClass()")
        del cls.good_range

    def setUp(self) -> None:
        super().setUp()
        print("\nIn setUp()")
        # 확실하게 범위 안에 있는 한 숫자를 선택한다.
        # 범위는 stop 값이 포함되지 않게 정의되므로, 이 값은 선택을 위한 값 집합에 포함돼서는 안된다.
        self.value = random.randint(self.good_range.start, self.good_range.stop - 1)

    def tearDown(self) -> None:
        print("In tearDown()")
        del self.value
        super().tearDown()

    def test1(self):
        print("In test1()")
        self.assertIn(self.value, self.good_range)

    def test2(self):
        print("In test2()")
        self.assertIn(self.value, self.good_range)
```

이 샘플 테스트를 실행해보면 픽스처와 테스트 메서드의 실행 순서가 분명히 드러난다.

```
$ python38  -u -m unittest -v unittest_fixtures.py
In setupModule()
In setUpClass()
test1 (unittest_fixtures.FixturesTest) ...
In setUp()
In test1()
In tearDown()
ok
test2 (unittest_fixtures.FixturesTest) ...
In setUp()
In test2()
In tearDown()
ok
In tearDownClass()
In tearDownModule()

----------------------------------------------------------------------
Ran 2 tests in 0.000s

OK
```

픽스처를 해제하는 과정에서 에러가 발생하면 tearDown 메서드가 모두 호출되지 않을수 있다. 픽스처를 항상 정확하게 해제하려면 addCleanup()을 사용한다.
